<?xml version = "1.0"?>
<robot name = "edu_rover">
<link name = "dummy_link">
    <collision>
        <origin xyz = "0 0 0" rpy = "0 0 0" />
        <geometry>
            <box size = "0.15 0.1 0.036"/>
        </geometry>
    </collision>
    <visual>
        <geometry>
            <box size = "0.01 0.01 0.01"/>
        </geometry>
    </visual>
    </link>

    <link name = "base_link">            
        <inertial>
            <origin xyz = "0 0 0" rpy = "0 0 0" />
            <mass value = "0.08"/>
            <inertia ixx = "0.00015864" ixy = "0.0" ixz = "0.0" iyy = "7.53066666667e-05" iyz = "0.0" izz = "0.0002166666667"/>
        </inertial>

        <collision>
            <origin xyz = "0 0 0" rpy = "0 0 0" />
            <geometry>
                <box size = "0.15 0.1 0.036"/>
            </geometry>
        </collision>

        <visual>
            <origin xyz ="0.011 -0.13 0" rpy = "0 0 4.72984"/>
            <geometry>
                <mesh filename="package://edu_rover/models/base.STL"/>
            </geometry>
        </visual>
    </link>

    <gazebo reference="base_link">
        <mu1>10.0</mu1>
        <mu2>10.0</mu2>
        <material>Gazebo/Blue</material>
    </gazebo>


    <joint name = "dummy_joint" type = "fixed">
        <parent link = "dummy_link"/>
        <child link = "base_link"/>
    </joint>
<!-- left_front ()-[III]-()
                   [III]
                   [III]
                ()-[III]-()
-->
    <link name = "left_front_knuckle">
        <inertial>
            <origin xyz = "0 0 0" rpy = "0 0 0"/>
            <mass value = "0.012"/>
            <inertia ixx = "2.9e-06" ixy = "0.0" ixz = "0.0" iyy = "8.0e-07" iyz = "0.0" izz = "2.9e-06"/>
        </inertial>

        <collision>
            <origin xyz = "0 0.025 0" rpy = "0 0 0"/>
            <geometry>
                <box size = "0.02 0.05 0.02" />
            </geometry>
        </collision>

        <visual>
            <origin xyz = "0 0 0" rpy = "1.5708 0 0"/>
            <geometry>
                <mesh filename="package://edu_rover/models/knuckle.STL"/>
            </geometry>
        </visual>
    </link>

    <gazebo reference = "left_front_knuckle">
        <material>Gazebo/Grey</material>
    </gazebo>

    <joint name = "left_front_knuckle_joint" type = "revolute">
        <parent link = "base_link"/>
        <child link = "left_front_knuckle"/>
        <origin xyz = "0.075 0.05 0" rpys = "0 0 0 "/>
        <limit lower = "-1.5708" upper = "0.52" effort = "1" velocity = "0.005"/>
        <axis xyz = "0 0 1"/> 
    </joint>

    <link name = "left_front_wheel">
        <inertial>
            <origin xyz = "0 0 0" rpy = "0 0 0"/>
            <mass value = "0.03"/>
            <inertia ixx = "1.225e-05" ixy = "0.0" ixz = "0.0" iyy = "1.225e-05" iyz = "0.0" izz = "2.4e-05"/>
        </inertial>

        <collision>
            <origin xyz = "0 0 0" rpy = "1.5708 0 0"/>
            <geometry>
                <cylinder radius = "0.04" length = "0.01"/>
            </geometry>
        </collision>

        <visual>
            <origin xyz = "0 0 0" rpy = "0 0 0"/>
            <geometry>
                <mesh filename="package://edu_rover/models/wheel.STL"/>
            </geometry>
        </visual>
    </link>

    <gazebo reference="left_front_wheel">
        <kp>1000.0</kp>
        <kd>1000.0</kd>
        <mu1>10.0</mu1>
        <mu2>10.0</mu2>
        <material>Gazebo/Black</material>
    </gazebo>


    <joint name = "left_front_wheel_joint" type = "continuous">
        <parent link = "left_front_knuckle"/>
        <child link = "left_front_wheel"/>
        <origin xyz = "0 0.05 0" rpy = "0 0 0" />
        <limit effort = "1" velocity = "0.05" />
        <axis xyz = " 0 1 0"/>
    </joint>

    <!--        ()-[III]-()
                   [III]
                   [III]
      left_front()-[III]-()
-->
    <link name = "left_back_knuckle">
        <inertial>
            <origin xyz = "0 0 0" rpy = "0 0 0"/>
            <mass value = "0.012"/>
            <inertia ixx = "2.9e-06" ixy = "0.0" ixz = "0.0" iyy = "8.0e-07" iyz = "0.0" izz = "2.9e-06"/>
        </inertial>

        <collision>
            <origin xyz = "0 0.025 0" rpy = "0 0 0"/>
            <geometry>
                <box size = "0.02 0.05 0.02" />
            </geometry>
        </collision>

        <visual>
            <origin xyz = "0 0 0" rpy = "1.5708 0 0"/>
            <geometry>
                <mesh filename="package://edu_rover/models/knuckle.STL"/>
            </geometry>
        </visual>
    </link>

    <gazebo reference = "left_back_knuckle">
        <material>Gazebo/Grey</material>
    </gazebo>

    <joint name = "left_back_knuckle_joint" type = "revolute">
        <parent link = "base_link"/>
        <child link = "left_back_knuckle"/>
        <origin xyz = "-0.075 0.05 0" rpys = "0 0 0"/>
        <limit lower = "1.5708" upper = "-0.52" effort = "1" velocity = "0.005"/>
        <axis xyz = "0 0 1"/> 
    </joint>

    <link name = "left_back_wheel">
        <inertial>
            <origin xyz = "0 0 0" rpy = "0 0 0"/>
            <mass value = "0.03"/>
            <inertia ixx = "1.225e-05" ixy = "0.0" ixz = "0.0" iyy = "1.225e-05" iyz = "0.0" izz = "2.4e-05"/>
        </inertial>

        <collision>
            <origin xyz = "0 0 0" rpy = "1.5708 0 0"/>
            <geometry>
                <cylinder radius = "0.04" length = "0.01"/>
            </geometry>
        </collision>

        <visual>
            <origin xyz = "0 0 0" rpy = "0 0 0"/>
            <geometry>
                <mesh filename="package://edu_rover/models/wheel.STL"/>
            </geometry>
        </visual>
    </link>

    <gazebo reference="left_back_wheel">
        <kp>1000.0</kp>
        <kd>1000.0</kd>
        <mu1>10.0</mu1>
        <mu2>10.0</mu2>
        <material>Gazebo/Black</material>
    </gazebo>

    <joint name = "left_back_wheel_joint" type = "continuous">
        <parent link = "left_back_knuckle"/>
        <child link = "left_back_wheel"/>
        <origin xyz = "0 0.05 0" rpy = "0 0 0" />
        <limit effort = "1" velocity = "0.05" />
        <axis xyz = " 0 1 0"/>
    </joint>

    <!-- ()-[III]-()right_front 
            [III]
            [III]
         ()-[III]-()
-->
    <link name = "right_front_knuckle">
        <inertial>
            <origin xyz = "0 0 0" rpy = "0 0 0"/>
            <mass value = "0.012"/>
            <inertia ixx = "2.9e-06" ixy = "0.0" ixz = "0.0" iyy = "8.0e-07" iyz = "0.0" izz = "2.9e-06"/>
        </inertial>

        <collision>
            <origin xyz = "0 -0.025 0" rpy = "0 0 0"/>
            <geometry>
                <box size = "0.02 0.05 0.02" />
            </geometry>
        </collision>

        <visual>
            <origin xyz = "0 0 0" rpy = "1.5708 0 3.14159"/>
            <geometry>
                <mesh filename="package://edu_rover/models/knuckle.STL"/>
            </geometry>
        </visual>
    </link>

    <gazebo reference = "right_front_knuckle">
        <material>Gazebo/Grey</material>
    </gazebo>

    <joint name = "right_front_knuckle_joint" type = "revolute">
        <parent link = "base_link"/>
        <child link = "right_front_knuckle"/>
        <origin xyz = "0.075 -0.05 0" rpys = "0 0 0 "/>
        <limit lower = "1.5708" upper = "-0.52" effort = "1" velocity = "0.005"/>
        <axis xyz = "0 0 1"/> 
    </joint>

    <link name = "right_front_wheel">
        <inertial>
            <origin xyz = "0 0 0" rpy = "0 0 0"/>
            <mass value = "0.03"/>
            <inertia ixx = "1.225e-05" ixy = "0.0" ixz = "0.0" iyy = "1.225e-05" iyz = "0.0" izz = "2.4e-05"/>
        </inertial>

        <collision>
            <origin xyz = "0 0 0" rpy = "1.5708 0 0"/>
            <geometry>
                <cylinder radius = "0.04" length = "0.01"/>
            </geometry>
        </collision>

        <visual>
            <origin xyz = "0 0 0" rpy = "0 0 3.14159"/>
            <geometry>
                <mesh filename="package://edu_rover/models/wheel.STL"/>
            </geometry>
        </visual>
    </link>

    <gazebo reference="right_front_wheel">
        <kp>1000.0</kp>
        <kd>1000.0</kd>
        <mu1>10.0</mu1>
        <mu2>10.0</mu2>
        <material>Gazebo/Black</material>
    </gazebo>

    <joint name = "right_front_wheel_joint" type = "continuous">
        <parent link = "right_front_knuckle"/>
        <child link = "right_front_wheel"/>
        <origin xyz = "0 -0.05 0" rpy = "0 0 0" />
        <limit effort = "1" velocity = "0.05" />
        <axis xyz = " 0 1 0"/>
    </joint>

    <!-- ()-[III]-()
            [III]
            [III]
         ()-[III]-()right_back 
-->
    <link name = "right_back_knuckle">
        <inertial>
            <origin xyz = "0 0 0" rpy = "0 0 0"/>
            <mass value = "0.012"/>
            <inertia ixx = "2.9e-06" ixy = "0.0" ixz = "0.0" iyy = "8.0e-07" iyz = "0.0" izz = "2.9e-06"/>
        </inertial>

        <collision>
            <origin xyz = "0 -0.025 0" rpy = "0 0 0"/>
            <geometry>
                <box size = "0.02 0.05 0.02" />
            </geometry>
        </collision>

        <visual>
            <origin xyz = "0 0 0" rpy = "1.5708 0 3.14159"/>
            <geometry>
                <mesh filename="package://edu_rover/models/knuckle.STL"/>
            </geometry>
        </visual>
    </link>

    <gazebo reference = "right_back_knuckle">
        <material>Gazebo/Grey</material>
    </gazebo>

    <joint name = "right_back_knuckle_joint" type = "revolute">
        <parent link = "base_link"/>
        <child link = "right_back_knuckle"/>
        <origin xyz = "-0.075 -0.05 0" rpys = "0 0 0"/>
        <limit lower = "-1.5708" upper = "0.52" effort = "1" velocity = "0.005"/>
        <axis xyz = "0 0 1"/> 
    </joint>

    <link name = "right_back_wheel">
        <inertial>
            <origin xyz = "0 0 0" rpy = "0 0 0"/>
            <mass value = "0.03"/>
            <inertia ixx = "1.225e-05" ixy = "0.0" ixz = "0.0" iyy = "1.225e-05" iyz = "0.0" izz = "2.4e-05"/>
        </inertial>

        <collision>
            <origin xyz = "0 0 0" rpy = "1.5708 0 0"/>
            <geometry>
                <cylinder radius = "0.04" length = "0.01"/>
            </geometry>
        </collision>

        <visual>
            <origin xyz = "0 0 0" rpy = "0 0 3.14159"/>
            <geometry>
                <mesh filename="package://edu_rover/models/wheel.STL"/>
            </geometry>
        </visual>
    </link>

    <gazebo reference="right_back_wheel">
        <kp>1000.0</kp>
        <kd>1000.0</kd>
        <mu1>10.0</mu1>
        <mu2>10.0</mu2>
        <material>Gazebo/Black</material>
    </gazebo>

    <joint name = "right_back_wheel_joint" type = "continuous">
        <parent link = "right_back_knuckle"/>
        <child link = "right_back_wheel"/>
        <origin xyz = "0 -0.05 0" rpy = "0 0 0" />
        <limit effort = "1" velocity = "0.05" />
        <axis xyz = " 0 1 0"/>
    </joint>
</robot>
