<?xml version = "1.0"?>
<robot name = "edu_rover">
    <link name = "base_link">
        <visual>
        <origin xyz ="0 0 0" rpy = "0 0 0"/>
        <geometry>
            <box size = "0.15 0.1 0.036"/>
        </geometry>
        </visual>
    </link>
<!-- left_front ()-[III]-()
                   [III]
                   [III]
                ()-[III]-()
-->
    <link name = "left_front_knuckle">
        <visual>
        <origin xyz = "0 0.025 0" rpy = "0 0 0"/>
        <geometry>
            <box size = "0.02 0.05 0.02" />
        </geometry>
        </visual>
    </link>

    <joint name = "left_front_knuckle_joint" type = "revolute">
        <parent link = "base_link"/>
        <child link = "left_front_knuckle"/>
        <origin xyz = "0.075 0.05 0" rpys = "0 0 0 "/>
        <limit lower = "-1.5708" upper = "0.52" effort = "1" velocity = "0.005"/>
        <axis xyz = "0 0 1"/> 
    </joint>

    <link name = "left_front_wheel">
    <visual>
    <origin xyz = "0 0 0" rpy = "1.5708 0 0"/>
    <geometry>
        <cylinder radius = "0.04" length = "0.01"/>
    </geometry>
    </visual>
    </link>

    <joint name = "left_front_wheel_joint" type = "continuous">
    <parent link = "left_front_knuckle"/>
    <child link = "left_front_wheel"/>
    <origin xyz = "0 0.05 0" rpy = "0 0 0" />
    <limit effort = "1" velocity = "0.05" />
    <axis xyz = " 0 1 0"/>
    </joint>

    <!--        ()-[III]-()
                   [III]
                   [III]
      left_front()-[III]-()
-->
    <link name = "left_back_knuckle">
        <visual>
        <origin xyz = "0 0.025 0" rpy = "0 0 0"/>
        <geometry>
            <box size = "0.02 0.05 0.02" />
        </geometry>
        </visual>
    </link>

    <joint name = "left_back_knuckle_joint" type = "revolute">
        <parent link = "base_link"/>
        <child link = "left_back_knuckle"/>
        <origin xyz = "-0.075 0.05 0" rpys = "0 0 0"/>
        <limit lower = "1.5708" upper = "-0.52" effort = "1" velocity = "0.005"/>
        <axis xyz = "0 0 1"/> 
    </joint>

    <link name = "left_back_wheel">
    <visual>
    <origin xyz = "0 0 0" rpy = "1.5708 0 0"/>
    <geometry>
        <cylinder radius = "0.04" length = "0.01"/>
    </geometry>
    </visual>
    </link>

    <joint name = "left_back_wheel_joint" type = "continuous">
    <parent link = "left_back_knuckle"/>
    <child link = "left_back_wheel"/>
    <origin xyz = "0 0.05 0" rpy = "0 0 0" />
    <limit effort = "1" velocity = "0.05" />
    <axis xyz = " 0 1 0"/>
    </joint>

    <!-- ()-[III]-()right_front 
            [III]
            [III]
         ()-[III]-()
-->
    <link name = "right_front_knuckle">
        <visual>
        <origin xyz = "0 -0.025 0" rpy = "0 0 0"/>
        <geometry>
            <box size = "0.02 0.05 0.02" />
        </geometry>
        </visual>
    </link>

    <joint name = "right_front_knuckle_joint" type = "revolute">
        <parent link = "base_link"/>
        <child link = "right_front_knuckle"/>
        <origin xyz = "0.075 -0.05 0" rpys = "0 0 0 "/>
        <limit lower = "1.5708" upper = "-0.52" effort = "1" velocity = "0.005"/>
        <axis xyz = "0 0 1"/> 
    </joint>

    <link name = "right_front_wheel">
    <visual>
    <origin xyz = "0 0 0" rpy = "1.5708 0 0"/>
    <geometry>
        <cylinder radius = "0.04" length = "0.01"/>
    </geometry>
    </visual>
    </link>

    <joint name = "right_front_wheel_joint" type = "continuous">
    <parent link = "right_front_knuckle"/>
    <child link = "right_front_wheel"/>
    <origin xyz = "0 -0.05 0" rpy = "0 0 0" />
    <limit effort = "1" velocity = "0.05" />
    <axis xyz = " 0 1 0"/>
    </joint>

    <!-- ()-[III]-()
            [III]
            [III]
         ()-[III]-()right_back 
-->
    <link name = "right_back_knuckle">
        <visual>
        <origin xyz = "0 -0.025 0" rpy = "0 0 0"/>
        <geometry>
            <box size = "0.02 0.05 0.02" />
        </geometry>
        </visual>
    </link>

    <joint name = "right_back_knuckle_joint" type = "revolute">
        <parent link = "base_link"/>
        <child link = "right_back_knuckle"/>
        <origin xyz = "-0.075 -0.05 0" rpys = "0 0 0"/>
        <limit lower = "-1.5708" upper = "0.52" effort = "1" velocity = "0.005"/>
        <axis xyz = "0 0 1"/> 
    </joint>

    <link name = "right_back_wheel">
    <visual>
    <origin xyz = "0 0 0" rpy = "1.5708 0 0"/>
    <geometry>
        <cylinder radius = "0.04" length = "0.01"/>
    </geometry>
    </visual>
    </link>

    <joint name = "right_back_wheel_joint" type = "continuous">
    <parent link = "right_back_knuckle"/>
    <child link = "right_back_wheel"/>
    <origin xyz = "0 -0.05 0" rpy = "0 0 0" />
    <limit effort = "1" velocity = "0.05" />
    <axis xyz = " 0 1 0"/>
    </joint>
</robot>